<?xml version="1.0"?>
<robot name="botanbot"
    xmlns:xacro="http://ros.org/wiki/xacro">
    <!-- BEGIN LINKS-->
    <!-- begin robot body links-->
    <link name="base_link">
        <visual>
            <origin xyz="-0.019375 0.005287 0.340756" rpy="0 0 0" />
            <geometry>
                <mesh filename="package://botanbot_description/meshes/base.stl"/>
            </geometry>
            <material name="Cyan">
                <color rgba="0 1.0 1.0 1.0" />
            </material>
        </visual>
        <collision>
            <origin xyz="-0.019375 0.005287 0.340756" rpy="0 0 0" />
            <geometry>
                <mesh filename="package://botanbot_description/meshes/base.stl"/>
            </geometry>
        </collision>
    </link>
    <link name='steering_wheel'>
        <visual name='visual'>
            <origin xyz="0 0 0" rpy="1.57 0 0" />
            <geometry>
                <mesh filename="package://botanbot_description/meshes/wheel.stl" scale="0.5 0.5 1" />
            </geometry>
            <material name="Red">
                <color rgba="1.0 0 0 0.6" />
            </material>
        </visual>
        <collision name='collision'>
            <geometry>
                <mesh filename="package://botanbot_description/meshes/wheel.stl" scale="0.5 0.5 1" />
            </geometry>
        </collision>
    </link>
    <link name='front_left_wheel'>
        <visual name='visual'>
            <origin xyz="0 0 0" rpy="0 0 1.57" />
            <geometry>
                <mesh filename="package://botanbot_description/meshes/wheel.stl" scale="1 1 1" />
            </geometry>
            <material name="Red">
                <color rgba="1.0 0 0 0.6" />
            </material>
        </visual>
        <collision name='collision'>
            <geometry>
                <mesh filename="package://botanbot_description/meshes/wheel.stl" scale="1 1 1" />
            </geometry>
        </collision>
    </link>
    <link name='front_right_wheel'>
        <visual name='visual'>
            <origin xyz="0 0 0" rpy="0 0 1.57" />
            <geometry>
                <mesh filename="package://botanbot_description/meshes/wheel.stl" scale="1 1 1" />
            </geometry>
            <material name="Red">
                <color rgba="1.0 0 0 0.6" />
            </material>
        </visual>
        <collision name='collision'>
            <geometry>
                <mesh filename="package://botanbot_description/meshes/wheel.stl" scale="1 1 1" />
            </geometry>
        </collision>
    </link>
    <link name='rear_left_wheel'>
        <visual name='visual'>
            <origin xyz="0 0 0" rpy="0 0 1.57" />
            <geometry>
                <mesh filename="package://botanbot_description/meshes/wheel.stl" scale="1 1 1" />
            </geometry>
            <material name="Red">
                <color rgba="1.0 0 0 0.6" />
            </material>
        </visual>
        <collision name='collision'>
            <geometry>
                <mesh filename="package://botanbot_description/meshes/wheel.stl" scale="1 1 1" />
            </geometry>
        </collision>
    </link>
    <link name='rear_right_wheel'>
        <visual name='visual'>
            <origin xyz="0 0 0" rpy="0 0 1.57" />
            <geometry>
                <mesh filename="package://botanbot_description/meshes/wheel.stl" scale="1 1 1" />
            </geometry>
            <material name="Red">
                <color rgba="1.0 0 0 0.6" />
            </material>
        </visual>
        <collision name='collision'>
            <geometry>
                <mesh filename="package://botanbot_description/meshes/wheel.stl" scale="1 1 1" />
            </geometry>
        </collision>
    </link>
    <link name='rear_axle'>
        <visual name='visual'>
            <origin xyz="0 0 0" rpy="1.57 -0 1.57" />
            <geometry>
                <cylinder radius="0.043346" length="0.694281" />
            </geometry>
            <material name="Cyan">
                <color rgba="0 1.0 1.0 1.0" />
            </material>
        </visual>
        <collision name='collision'>
            <origin xyz="0 0 0" rpy="1.57 -0 1.57" />
            <geometry>
                <cylinder radius="0.043346" length="0.694281" />
            </geometry>
        </collision>
    </link>
    <!-- end robot body links-->
    <!-- begin sensor links-->
    <link name='imu_link'>
        <visual name='visual'>
            <geometry>
                <cylinder radius="0.001" length="0.011" />
            </geometry>
            <material name="Red">
                <color rgba="1.0 0 0 0.6" />
            </material>
        </visual>
        <collision name='collision'>
            <geometry>
                <cylinder radius="0.001" length="0.011" />
            </geometry>
        </collision>
    </link>
    <link name="velodyne_link">
        <visual>
            <geometry>
                <mesh filename="package://botanbot_description/meshes/lidar.stl" scale="0.001 0.001 0.001" />
            </geometry>
        </visual>
        <collision>
            <geometry>
                <mesh filename="package://botanbot_description/meshes/lidar.stl" scale="0.001 0.001 0.001" />
            </geometry>
        </collision>
    </link>
    <link name="gps">
        <visual>
            <geometry>
                <mesh filename="package://botanbot_description/meshes/gps.stl" scale="0.0005 0.0005 0.001" />
            </geometry>
        </visual>
        <collision>
            <geometry>
                <mesh filename="package://botanbot_description/meshes/gps.stl" scale="0.0005 0.0005 0.001" />
            </geometry>
        </collision>
    </link>
    <link name="camera_bottom_screw_frame">
        <visual>
            <geometry>
                <mesh filename="package://botanbot_description/meshes/d435.dae" />
            </geometry>
        </visual>
        <collision>
            <geometry>
                <mesh filename="package://botanbot_description/meshes/d435.dae" />
            </geometry>
        </collision>
    </link>
    <link name="camera_link"></link>
    <link name="camera_depth_frame"></link>
    <link name="camera_depth_optical_frame"></link>
    <link name="camera_color_frame"></link>
    <link name="camera_color_optical_frame"></link>
    <link name="camera_left_ir_frame"></link>
    <link name="camera_left_ir_optical_frame"></link>
    <link name="camera_right_ir_frame"></link>
    <link name="camera_right_ir_optical_frame"></link>
    <!-- end sensor links-->
    <!-- END LINKS-->
    <!--  BEGIN  JOINTS-->
    <!-- begin robot body joints-->
    <joint name='front_left_combined_joint' type='continuous'>
        <parent link="base_link" />
        <child link="front_left_wheel" />
        <origin xyz="0.653624 0.496194 -0.084805" rpy="0 -0 1.5706" />
        <axis xyz="0 0 1" />
    </joint>
    <joint name='front_right_combined_joint' type='continuous'>
        <parent link="base_link" />
        <child link="front_right_wheel" />
        <origin xyz="0.666123 -0.495391 -0.085288" rpy="0 0 1.5706" />
        <axis xyz="0 0 1" />
    </joint>
    <joint name='rear_axle_joint' type='continuous'>
        <parent link="base_link" />
        <child link="rear_axle" />
        <origin xyz="-0.656403 0.001088 -0.085593" rpy="0 0 1.57" />
        <dynamics damping="2000.0" friction="0.0"/>
        <limit effort="0" velocity="0.0" lower="-0.05" upper="0.05" />
        <axis xyz="0 1 0" />
    </joint>
    <joint name='rear_left_joint' type='continuous'>
        <parent link="base_link" />
        <child link="rear_left_wheel" />
        <origin xyz="-0.656583 0.492236 -0.085593" rpy="0 -0 1.5706" />
        <axis xyz="1 0 0" />
    </joint>
    <joint name='rear_right_joint' type='continuous'>
        <parent link="base_link" />
        <child link="rear_right_wheel" />
        <origin xyz="-0.644212 -0.499228 -0.085214" rpy="0 -0 1.5706" />
        <axis xyz="1 0 0" />
    </joint>
    <joint name='steering_joint' type='continuous'>
        <parent link="base_link" />
        <child link="steering_wheel" />
        <origin xyz="0.400132 9.3e-05 0.399996" rpy="0 -1.57 0" />
        <axis xyz="0 0 1" />
    </joint>
    <!-- end robot body joints-->
    <!-- begin sensor joints-->
    <joint name="imu_joint" type="fixed">
        <parent link="base_link" />
        <child link="imu_link" />
        <origin xyz="0.7 0.5 0.6" rpy="0 0 0" />
    </joint>
    <joint name="velodyne_joint" type="fixed">
        <parent link="base_link" />
        <child link="velodyne_link" />
        <origin xyz="0 0 0.9" rpy="0 0 0" />
    </joint>
    <joint name="gps_joint" type="fixed">
        <parent link="base_link" />
        <child link="gps" />
        <origin xyz="0 0 0.4" rpy="0 0 0" />
    </joint>
    <joint name="camera_joint" type="fixed">
        <parent link="base_link" />
        <child link="camera_bottom_screw_frame" />
        <pose xyz="0.7 -0.5 0.6" rpy="-1.57 0 -1.57" />
    </joint>
    <joint name="camera_link_joint" type="fixed">
        <parent link="camera_bottom_screw_frame" />
        <child link="camera_link" />
        <pose xyz="0 0.0175 0.0125 " rpy="0 0 0" />
    </joint>
    <joint name="camera_depth_joint" type="fixed">
        <parent link="camera_link" />
        <child link="camera_depth_frame" />
        <pose xyz="0 0 0" rpy="0 0 0" />
    </joint>
    <joint name="camera_depth_optical_joint" type="fixed">
        <parent link="camera_depth_frame" />
        <child link="camera_depth_optical_frame" />
        <pose xyz="0 0 0 " rpy="-1.57 0 -1.57" />
    </joint>
    <joint name="camera_color_joint" type="fixed">
        <parent link="camera_depth_frame" />
        <child link="camera_color_frame" />
        <pose xyz="0 0 0" rpy="0 0 0" />
    </joint>
    <joint name="camera_color_optical_joint" type="fixed">
        <parent link="camera_color_frame" />
        <child link="camera_color_optical_frame" />
        <pose xyz="0 0 0 " rpy="-1.57 0 -1.57" />
    </joint>
    <joint name="camera_left_ir_joint" type="fixed">
        <parent link="camera_depth_frame" />
        <child link="camera_left_ir_frame" />
        <pose xyz="0 0 0 " rpy="0 0 0 " />
    </joint>
    <joint name="camera_left_ir_optical_joint" type="fixed">
        <parent link="camera_left_ir_frame" />
        <child link="camera_left_ir_optical_frame" />
        <pose xyz="0 0 0 " rpy="-1.57 0 -1.57" />
    </joint>
    <joint name="camera_right_ir_joint" type="fixed">
        <parent link="camera_depth_frame" />
        <child link="camera_right_ir_frame" />
        <pose xyz="0 -0.050 0 " rpy="0 0 0" />
    </joint>
    <joint name="camera_right_ir_optical_joint" type="fixed">
        <parent link="camera_right_ir_frame" />
        <child link="camera_right_ir_optical_frame" />
        <pose xyz="0 0 0 " rpy="-1.57 0 -1.57" />
    </joint>
    <!-- end sensor joints-->
    <!-- END JOINTS-->
</robot>